2018-12-20 17:09:39,523 ERROR: Exception on /login [GET] [in c:\users\administrator\.virtualenvs\flask_mega-w9aju0jb\lib\site-packages\flask\app.py:1761]
Traceback (most recent call last):
  File "c:\users\administrator\.virtualenvs\flask_mega-w9aju0jb\lib\site-packages\flask\app.py", line 2292, in wsgi_app
    response = self.full_dispatch_request()
  File "c:\users\administrator\.virtualenvs\flask_mega-w9aju0jb\lib\site-packages\flask\app.py", line 1815, in full_dispatch_request
    rv = self.handle_user_exception(e)
  File "c:\users\administrator\.virtualenvs\flask_mega-w9aju0jb\lib\site-packages\flask\app.py", line 1718, in handle_user_exception
    reraise(exc_type, exc_value, tb)
  File "c:\users\administrator\.virtualenvs\flask_mega-w9aju0jb\lib\site-packages\flask\_compat.py", line 35, in reraise
    raise value
  File "c:\users\administrator\.virtualenvs\flask_mega-w9aju0jb\lib\site-packages\flask\app.py", line 1813, in full_dispatch_request
    rv = self.dispatch_request()
  File "c:\users\administrator\.virtualenvs\flask_mega-w9aju0jb\lib\site-packages\flask\app.py", line 1799, in dispatch_request
    return self.view_functions[rule.endpoint](**req.view_args)
  File "C:\Users\Administrator\PycharmProjects\Flask_Mega\app\routes.py", line 69, in login
    if form.validate_on_submit():
NameError: name 'form' is not defined
2018-12-20 17:09:39,664 ERROR: Exception on /login [GET] [in c:\users\administrator\.virtualenvs\flask_mega-w9aju0jb\lib\site-packages\flask\app.py:1761]
Traceback (most recent call last):
  File "c:\users\administrator\.virtualenvs\flask_mega-w9aju0jb\lib\site-packages\flask\app.py", line 2292, in wsgi_app
    response = self.full_dispatch_request()
  File "c:\users\administrator\.virtualenvs\flask_mega-w9aju0jb\lib\site-packages\flask\app.py", line 1815, in full_dispatch_request
    rv = self.handle_user_exception(e)
  File "c:\users\administrator\.virtualenvs\flask_mega-w9aju0jb\lib\site-packages\flask\app.py", line 1718, in handle_user_exception
    reraise(exc_type, exc_value, tb)
  File "c:\users\administrator\.virtualenvs\flask_mega-w9aju0jb\lib\site-packages\flask\_compat.py", line 35, in reraise
    raise value
  File "c:\users\administrator\.virtualenvs\flask_mega-w9aju0jb\lib\site-packages\flask\app.py", line 1813, in full_dispatch_request
    rv = self.dispatch_request()
  File "c:\users\administrator\.virtualenvs\flask_mega-w9aju0jb\lib\site-packages\flask\app.py", line 1799, in dispatch_request
    return self.view_functions[rule.endpoint](**req.view_args)
  File "C:\Users\Administrator\PycharmProjects\Flask_Mega\app\routes.py", line 69, in login
    if form.validate_on_submit():
NameError: name 'form' is not defined
2018-12-20 17:09:39,810 ERROR: Exception on /login [GET] [in c:\users\administrator\.virtualenvs\flask_mega-w9aju0jb\lib\site-packages\flask\app.py:1761]
Traceback (most recent call last):
  File "c:\users\administrator\.virtualenvs\flask_mega-w9aju0jb\lib\site-packages\flask\app.py", line 2292, in wsgi_app
    response = self.full_dispatch_request()
  File "c:\users\administrator\.virtualenvs\flask_mega-w9aju0jb\lib\site-packages\flask\app.py", line 1815, in full_dispatch_request
    rv = self.handle_user_exception(e)
  File "c:\users\administrator\.virtualenvs\flask_mega-w9aju0jb\lib\site-packages\flask\app.py", line 1718, in handle_user_exception
    reraise(exc_type, exc_value, tb)
  File "c:\users\administrator\.virtualenvs\flask_mega-w9aju0jb\lib\site-packages\flask\_compat.py", line 35, in reraise
    raise value
  File "c:\users\administrator\.virtualenvs\flask_mega-w9aju0jb\lib\site-packages\flask\app.py", line 1813, in full_dispatch_request
    rv = self.dispatch_request()
  File "c:\users\administrator\.virtualenvs\flask_mega-w9aju0jb\lib\site-packages\flask\app.py", line 1799, in dispatch_request
    return self.view_functions[rule.endpoint](**req.view_args)
  File "C:\Users\Administrator\PycharmProjects\Flask_Mega\app\routes.py", line 69, in login
    if form.validate_on_submit():
NameError: name 'form' is not defined
2018-12-20 17:09:39,978 ERROR: Exception on /login [GET] [in c:\users\administrator\.virtualenvs\flask_mega-w9aju0jb\lib\site-packages\flask\app.py:1761]
Traceback (most recent call last):
  File "c:\users\administrator\.virtualenvs\flask_mega-w9aju0jb\lib\site-packages\flask\app.py", line 2292, in wsgi_app
    response = self.full_dispatch_request()
  File "c:\users\administrator\.virtualenvs\flask_mega-w9aju0jb\lib\site-packages\flask\app.py", line 1815, in full_dispatch_request
    rv = self.handle_user_exception(e)
  File "c:\users\administrator\.virtualenvs\flask_mega-w9aju0jb\lib\site-packages\flask\app.py", line 1718, in handle_user_exception
    reraise(exc_type, exc_value, tb)
  File "c:\users\administrator\.virtualenvs\flask_mega-w9aju0jb\lib\site-packages\flask\_compat.py", line 35, in reraise
    raise value
  File "c:\users\administrator\.virtualenvs\flask_mega-w9aju0jb\lib\site-packages\flask\app.py", line 1813, in full_dispatch_request
    rv = self.dispatch_request()
  File "c:\users\administrator\.virtualenvs\flask_mega-w9aju0jb\lib\site-packages\flask\app.py", line 1799, in dispatch_request
    return self.view_functions[rule.endpoint](**req.view_args)
  File "C:\Users\Administrator\PycharmProjects\Flask_Mega\app\routes.py", line 69, in login
    if form.validate_on_submit():
NameError: name 'form' is not defined
2018-12-20 17:09:40,137 ERROR: Exception on /login [GET] [in c:\users\administrator\.virtualenvs\flask_mega-w9aju0jb\lib\site-packages\flask\app.py:1761]
Traceback (most recent call last):
  File "c:\users\administrator\.virtualenvs\flask_mega-w9aju0jb\lib\site-packages\flask\app.py", line 2292, in wsgi_app
    response = self.full_dispatch_request()
  File "c:\users\administrator\.virtualenvs\flask_mega-w9aju0jb\lib\site-packages\flask\app.py", line 1815, in full_dispatch_request
    rv = self.handle_user_exception(e)
  File "c:\users\administrator\.virtualenvs\flask_mega-w9aju0jb\lib\site-packages\flask\app.py", line 1718, in handle_user_exception
    reraise(exc_type, exc_value, tb)
  File "c:\users\administrator\.virtualenvs\flask_mega-w9aju0jb\lib\site-packages\flask\_compat.py", line 35, in reraise
    raise value
  File "c:\users\administrator\.virtualenvs\flask_mega-w9aju0jb\lib\site-packages\flask\app.py", line 1813, in full_dispatch_request
    rv = self.dispatch_request()
  File "c:\users\administrator\.virtualenvs\flask_mega-w9aju0jb\lib\site-packages\flask\app.py", line 1799, in dispatch_request
    return self.view_functions[rule.endpoint](**req.view_args)
  File "C:\Users\Administrator\PycharmProjects\Flask_Mega\app\routes.py", line 69, in login
    if form.validate_on_submit():
NameError: name 'form' is not defined
2018-12-20 17:12:02,194 INFO: Microblog startup [in C:\Users\Administrator\PycharmProjects\Flask_Mega\app\__init__.py:49]
